Workbook

Sheet Sheet1
A1: id | B1: surveyPeriodId | C1: mode | D1: assignmentErrorStatusType | E1: approvedByCreator | F1: codeIdentity | G1: assignmentStatusId | H1: assignmentStatusAlias | I1: isTarikSample | J1: data1 | K1: data2 | L1: data3 | M1: data4 | N1: data5 | O1: data6 | P1: data7 | Q1: data8 | R1: data9 | S1: data10 | T1: dateCreated | U1: isActive | V1: sumError | W1: sumRemark | X1: sumClean | Y1: done | Z1: secondary | AA1: longitude | AB1: latitude | AC1: externalDone | AD1: email | AE1: sourceFrom | AF1: listing | AG1: dateModified | AH1: assignmentResponsibility | AI1: assignmentResponsibilityAdmin | AJ1: region | AK1: regionMetadata | AL1: sampleType | AM1: isTarget | AN1: referencedTo | AO1: lockedByUser | AP1: lockedByAnother | AQ1: _partisi
A2: 472a7071-f7d1-4f06-890f-34616d6fa8fb | B2: 28539715-1be1-450e-8d63-2e8ef0dd0596 | C2: ["CAWI"] | D2: 4 | E2: FALSE | F2: 3604 | G2: 0 | H2: DRAFT | I2: FALSE | J2: PT. Nicomas Gemilang (Pengelola Kawasan Industri Nikomas Gemilang) | K2: Jl. Raya Serang - Jkt No.KM, RW.71, Tambak, Kec. Kibin, Kabupaten Serang, Banten 42185 | M2: alek.rhmn@pci.co.id | N2: 97066525 | O2: 8120219171441 | T2: 2026-04-28T09:30:32.285+00:00 | U2: TRUE | V2: 0 | W2: 0 | X2: 0 | Y2: FALSE | Z2: FALSE | AA2: 0 | AB2: 0 | AC2: FALSE | AD2: adnan_fs@gmail.com | AE2: U-CAWI | AF2: FALSE | AG2: 2026-05-11T02:10:51.094+00:00 | AH2: [] | AI2: [] | AJ2: {"id": "71723978-814a-463d-a4cd-e1c582fbd163", "groupId": "106eaacb-2e9d-4f2d-b436-9c1abdacd45e", "versionCode": 1.0, "dateCreated": "2025-04-26T17:20:35.082+00:00", "isActive": true, "level1": {"id": "89dde136-a5c9-4325-ab78-2d382087f68e", "fullCode": "36", "code": "36", "name": "BANTEN", "level2": {"id": "71723978-814a-463d-a4cd-e1c582fbd163", "fullCode": "3604", "code": "04", "name": "SERANG"}}} | AK2: {"id": "106eaacb-2e9d-4f2d-b436-9c1abdacd45e", "levelCount": 2, "smallestRegionLevel": "Kabupaten", "groupName": "MFD Feb25 KABUPATEN", "level": [{"id": 1, "name": "Provinsi"}, {"id": 2, "name": "Kabupaten"}]} | AL2: 1 | AM2: TRUE | AN2: [] | AO2: FALSE | AP2: FALSE | AQ2: PROVINSI
A3: a1bc8fb3-ee34-4be5-bd2f-d90d416a55c1 | B3: 28539715-1be1-450e-8d63-2e8ef0dd0596 | C3: ["CAWI"] | D3: 4 | E3: FALSE | F3: 3601 | G3: 0 | H3: DRAFT | I3: FALSE | J3: BANTEN WEST JAVA TOURISM DEVELOPMENT, PT | K3: Kawasan Pariwisata Tanjung Lesung Kav. R-14B , Desa/Kelurahan Tanjungjaya, Kec. Panimbang, Kab. Pandeglang, Provinsi Banten | M3: Bantenwestjava@gmail.com | N3: 2597036 | O3: 8120314182821 | T3: 2026-04-28T09:30:27.934+00:00 | U3: TRUE | V3: 0 | W3: 0 | X3: 0 | Y3: FALSE | Z3: FALSE | AA3: 0 | AB3: 0 | AC3: FALSE | AD3: Bantenwestjava@gmail.com | AE3: U-CAWI | AF3: FALSE | AG3: 2026-05-11T02:07:28.890+00:00 | AH3: [] | AI3: [] | AJ3: {"id": "2f16d13b-ee82-4892-942b-5130976b3b4a", "groupId": "106eaacb-2e9d-4f2d-b436-9c1abdacd45e", "versionCode": 1.0, "dateCreated": "2025-04-26T17:20:35.045+00:00", "isActive": true, "level1": {"id": "89dde136-a5c9-4325-ab78-2d382087f68e", "fullCode": "36", "code": "36", "name": "BANTEN", "level2": {"id": "2f16d13b-ee82-4892-942b-5130976b3b4a", "fullCode": "3601", "code": "01", "name": "PANDEGLANG"}}} | AK3: {"id": "106eaacb-2e9d-4f2d-b436-9c1abdacd45e", "levelCount": 2, "smallestRegionLevel": "Kabupaten", "groupName": "MFD Feb25 KABUPATEN", "level": [{"id": 1, "name": "Provinsi"}, {"id": 2, "name": "Kabupaten"}]} | AL3: 1 | AM3: TRUE | AN3: [] | AO3: FALSE | AP3: FALSE | AQ3: PROVINSI
A4: 898486c7-a9b6-4e7f-8e0c-bd47dad64aec | B4: 28539715-1be1-450e-8d63-2e8ef0dd0596 | C4: ["CAWI"] | D4: 1 | E4: FALSE | F4: 9120200800357 | G4: 0 | H4: OPEN | I4: FALSE | J4: Universitas Ichsan Satya | K4: Cluster Sudimara Jombang No. 18, Kelurahan Jombang, Kec. Ciputat, Tangerang Selatan, Banten | T4: 2026-05-11T01:49:58.545+00:00 | U4: TRUE | V4: 0 | W4: 0 | X4: 0 | Y4: FALSE | Z4: FALSE | AC4: FALSE | AD4: hrd.uisbintaro@gmail.com | AF4: FALSE | AG4: 2026-05-11T01:49:58.545+00:00 | AH4: [] | AI4: [] | AJ4: {"id": "3c7d6867-32a0-4006-9d0a-b8d39ff646d1", "groupId": "106eaacb-2e9d-4f2d-b436-9c1abdacd45e", "versionCode": 1.0, "dateCreated": "2025-04-26T17:20:35.126+00:00", "isActive": true, "level1": {"id": "89dde136-a5c9-4325-ab78-2d382087f68e", "fullCode": "36", "code": "36", "name": "BANTEN", "level2": {"id": "3c7d6867-32a0-4006-9d0a-b8d39ff646d1", "fullCode": "3674", "code": "74", "name": "TANGERANG SELATAN"}}} | AK4: {"id": "106eaacb-2e9d-4f2d-b436-9c1abdacd45e", "levelCount": 2, "smallestRegionLevel": "Kabupaten", "groupName": "MFD Feb25 KABUPATEN", "level": [{"id": 1, "name": "Provinsi"}, {"id": 2, "name": "Kabupaten"}]} | AL4: 1 | AM4: TRUE | AN4: [] | AO4: FALSE | AP4: FALSE | AQ4: PROVINSI
A5: e5160765-1431-48fa-a33a-c9a28875b335 | B5: 28539715-1be1-450e-8d63-2e8ef0dd0596 | C5: ["CAWI"] | D5: 4 | E5: FALSE | F5: 3603 | G5: 0 | H5: DRAFT | I5: FALSE | J5: Putera Daya Perkasa, PT PNDN | K5: Jalan Raya Pasar Kemis Km 7 rt 003 rw 003 Ds Suka Asih Pasar Kemis Kab Tangerang Banten | N5: 7479119 | O5: 10505220001783 | T5: 2026-04-28T09:30:29.185+00:00 | U5: TRUE | V5: 0 | W5: 0 | X5: 0 | Y5: FALSE | Z5: FALSE | AA5: 0 | AB5: 0 | AC5: FALSE | AD5: puteradayaperkasa@gmail.com | AE5: U-CAWI | AF5: FALSE | AG5: 2026-05-09T08:10:25.940+00:00 | AH5: [] | AI5: [] | AJ5: {"id": "4dbdaf00-9318-4ea5-91e0-0fb0814f5c04", "groupId": "106eaacb-2e9d-4f2d-b436-9c1abdacd45e", "versionCode": 1.0, "dateCreated": "2025-04-26T17:20:35.071+00:00", "isActive": true, "level1": {"id": "89dde136-a5c9-4325-ab78-2d382087f68e", "fullCode": "36", "code": "36", "name": "BANTEN", "level2": {"id": "4dbdaf00-9318-4ea5-91e0-0fb0814f5c04", "fullCode": "3603", "code": "03", "name": "TANGERANG"}}} | AK5: {"id": "106eaacb-2e9d-4f2d-b436-9c1abdacd45e", "levelCount": 2, "smallestRegionLevel": "Kabupaten", "groupName": "MFD Feb25 KABUPATEN", "level": [{"id": 1, "name": "Provinsi"}, {"id": 2, "name": "Kabupaten"}]} | AL5: 1 | AM5: TRUE | AN5: [] | AO5: FALSE | AP5: FALSE | AQ5: PROVINSI
A6: 99bd5047-2933-4739-a343-fe253ecb6090 | B6: 28539715-1be1-450e-8d63-2e8ef0dd0596 | C6: ["CAWI"] | D6: 4 | E6: FALSE | F6: 8120310033308 | G6: 0 | H6: DRAFT | I6: FALSE | J6: Yayasan Pendidikan Insan Pembangunan | K6: Jl. Raya Serang KM. 10, Bitung, Tangerang, Banten | M6: info@unipem.ac.id | T6: 2026-05-08T07:52:58.930+00:00 | U6: TRUE | V6: 0 | W6: 0 | X6: 0 | Y6: FALSE | Z6: FALSE | AA6: 0 | AB6: 0 | AC6: FALSE | AD6: info@unipem.ac.id | AE6: CAWI | AF6: FALSE | AG6: 2026-05-09T06:04:58.727+00:00 | AH6: [] | AI6: [] | AJ6: {"id": "4dbdaf00-9318-4ea5-91e0-0fb0814f5c04", "groupId": "106eaacb-2e9d-4f2d-b436-9c1abdacd45e", "versionCode": 1.0, "dateCreated": "2025-04-26T17:20:35.071+00:00", "isActive": true, "level1": {"id": "89dde136-a5c9-4325-ab78-2d382087f68e", "fullCode": "36", "code": "36", "name": "BANTEN", "level2": {"id": "4dbdaf00-9318-4ea5-91e0-0fb0814f5c04", "fullCode": "3603", "code": "03", "name": "TANGERANG"}}} | AK6: {"id": "106eaacb-2e9d-4f2d-b436-9c1abdacd45e", "levelCount": 2, "smallestRegionLevel": "Kabupaten", "groupName": "MFD Feb25 KABUPATEN", "level": [{"id": 1, "name": "Provinsi"}, {"id": 2, "name": "Kabupaten"}]} | AL6: 1 | AM6: TRUE | AN6: [] | AO6: FALSE | AP6: FALSE | AQ6: PROVINSI
A7: b3836adf-9133-40a9-b7df-54ff76cfd593 | B7: 28539715-1be1-450e-8d63-2e8ef0dd0596 | C7: ["CAWI"] | D7: 4 | E7: FALSE | F7: 3603 | G7: 0 | H7: DRAFT | I7: FALSE | J7: PT. Bangun Laksana Persada | K7: Marketing Gallery Agung Intiland, Jl. Raya Kali Baru, Desa Laksana, Kecamatan Pakuhaji, Kabupaten Tangerang, Banten | N7: 3589409 | O7: 8120014171632 | T7: 2026-04-28T09:30:30.852+00:00 | U7: TRUE | V7: 0 | W7: 0 | X7: 0 | Y7: FALSE | Z7: FALSE | AA7: 0 | AB7: 0 | AC7: FALSE | AD7: harianto.widjaja@agungintiland.com | AE7: U-CAWI | AF7: FALSE | AG7: 2026-05-09T04:17:58.955+00:00 | AH7: [] | AI7: [] | AJ7: {"id": "4dbdaf00-9318-4ea5-91e0-0fb0814f5c04", "groupId": "106eaacb-2e9d-4f2d-b436-9c1abdacd45e", "versionCode": 1.0, "dateCreated": "2025-04-26T17:20:35.071+00:00", "isActive": true, "level1": {"id": "89dde136-a5c9-4325-ab78-2d382087f68e", "fullCode": "36", "code": "36", "name": "BANTEN", "level2": {"id": "4dbdaf00-9318-4ea5-91e0-0fb0814f5c04", "fullCode": "3603", "code": "03", "name": "TANGERANG"}}} | AK7: {"id": "106eaacb-2e9d-4f2d-b436-9c1abdacd45e", "levelCount": 2, "smallestRegionLevel": "Kabupaten", "groupName": "MFD Feb25 KABUPATEN", "level": [{"id": 1, "name": "Provinsi"}, {"id": 2, "name": "Kabupaten"}]} | AL7: 1 | AM7: TRUE | AN7: [] | AO7: FALSE | AP7: FALSE | AQ7: PROVINSI
A8: 14e2fb38-a216-4598-a719-1f1f381f2446 | B8: 28539715-1be1-450e-8d63-2e8ef0dd0596 | C8: ["CAWI"] | D8: 4 | E8: FALSE | F8: 3673 | G8: 5 | H8: SUBMITTED RESPONDENT | I8: FALSE | J8: Universitas Bina Bangsa | K8: Jl. Raya Serang Jakarta Km.03 No. 1.B (Pakupatan) Kota Serang Banten | M8: kerjasama@binabangsa.ac.id | N8: 6492913 | T8: 2026-04-28T09:30:36.857+00:00 | U8: TRUE | V8: 0 | W8: 0 | X8: 0 | Y8: FALSE | Z8: FALSE | AA8: 0 | AB8: 0 | AC8: TRUE | AD8: gatot.hartoko@yahoo.co.id | AE8: U-CAWI | AF8: FALSE | AG8: 2026-05-09T04:00:15.778+00:00 | AH8: [] | AI8: [] | AJ8: {"id": "928a6a1c-6a9d-467c-84b7-8807a54f5e68", "groupId": "106eaacb-2e9d-4f2d-b436-9c1abdacd45e", "versionCode": 1.0, "dateCreated": "2025-04-26T17:20:35.115+00:00", "isActive": true, "level1": {"id": "89dde136-a5c9-4325-ab78-2d382087f68e", "fullCode": "36", "code": "36", "name": "BANTEN", "level2": {"id": "928a6a1c-6a9d-467c-84b7-8807a54f5e68", "fullCode": "3673", "code": "73", "name": "SERANG"}}} | AK8: {"id": "106eaacb-2e9d-4f2d-b436-9c1abdacd45e", "levelCount": 2, "smallestRegionLevel": "Kabupaten", "groupName": "MFD Feb25 KABUPATEN", "level": [{"id": 1, "name": "Provinsi"}, {"id": 2, "name": "Kabupaten"}]} | AL8: 1 | AM8: TRUE | AN8: [] | AO8: FALSE | AP8: FALSE | AQ8: PROVINSI
A9: 262a98b3-fdf5-49a2-91a7-dd775134a4c9 | B9: 28539715-1be1-450e-8d63-2e8ef0dd0596 | C9: ["CAWI"] | D9: 4 | E9: FALSE | F9: NIBmowm6n4728 | G9: 0 | H9: DRAFT | I9: FALSE | J9: Universitas Pamulang | K9: JL. SURYA KENCANA NO. 1, PAMULANG BARAT, KEC. PAMULANG, KOTA TANGERANG SELATAN | M9: humas@unpam.ac.id | T9: 2026-05-08T07:54:55.253+00:00 | U9: TRUE | V9: 0 | W9: 0 | X9: 0 | Y9: FALSE | Z9: FALSE | AA9: 0 | AB9: 0 | AC9: FALSE | AD9: humas@unpam.ac.id | AE9: CAWI | AF9: FALSE | AG9: 2026-05-08T09:52:36.454+00:00 | AH9: [] | AI9: [] | AJ9: {"id": "3c7d6867-32a0-4006-9d0a-b8d39ff646d1", "groupId": "106eaacb-2e9d-4f2d-b436-9c1abdacd45e", "versionCode": 1.0, "dateCreated": "2025-04-26T17:20:35.126+00:00", "isActive": true, "level1": {"id": "89dde136-a5c9-4325-ab78-2d382087f68e", "fullCode": "36", "code": "36", "name": "BANTEN", "level2": {"id": "3c7d6867-32a0-4006-9d0a-b8d39ff646d1", "fullCode": "3674", "code": "74", "name": "TANGERANG SELATAN"}}} | AK9: {"id": "106eaacb-2e9d-4f2d-b436-9c1abdacd45e", "levelCount": 2, "smallestRegionLevel": "Kabupaten", "groupName": "MFD Feb25 KABUPATEN", "level": [{"id": 1, "name": "Provinsi"}, {"id": 2, "name": "Kabupaten"}]} | AL9: 1 | AM9: TRUE | AN9: [] | AO9: FALSE | AP9: FALSE | AQ9: PROVINSI
A10: 3537f5ad-8c05-4cae-8874-9a5074e8dc6c | B10: 28539715-1be1-450e-8d63-2e8ef0dd0596 | C10: ["CAWI"] | D10: 4 | E10: FALSE | F10: 0265010231748 | G10: 0 | H10: DRAFT | I10: FALSE | J10: Institut Teknologi dan Bisnis Bina Sarana Global | K10: Jl.Aria Santika No.43 Margasari,Kec.Karawaci,Kota Tangerang | M10: hrd@global.ac.id | O10: 0265010231748 | T10: 2026-05-08T07:59:59.900+00:00 | U10: TRUE | V10: 0 | W10: 0 | X10: 0 | Y10: FALSE | Z10: FALSE | AA10: 0 | AB10: 0 | AC10: FALSE | AD10: hrd@global.ac.id | AE10: CAWI | AF10: FALSE | AG10: 2026-05-08T09:15:15.141+00:00 | AH10: [] | AI10: [] | AJ10: {"id": "4dbdaf00-9318-4ea5-91e0-0fb0814f5c04", "groupId": "106eaacb-2e9d-4f2d-b436-9c1abdacd45e", "versionCode": 1.0, "dateCreated": "2025-04-26T17:20:35.071+00:00", "isActive": true, "level1": {"id": "89dde136-a5c9-4325-ab78-2d382087f68e", "fullCode": "36", "code": "36", "name": "BANTEN", "level2": {"id": "4dbdaf00-9318-4ea5-91e0-0fb0814f5c04", "fullCode": "3603", "code": "03", "name": "TANGERANG"}}} | AK10: {"id": "106eaacb-2e9d-4f2d-b436-9c1abdacd45e", "levelCount": 2, "smallestRegionLevel": "Kabupaten", "groupName": "MFD Feb25 KABUPATEN", "level": [{"id": 1, "name": "Provinsi"}, {"id": 2, "name": "Kabupaten"}]} | AL10: 1 | AM10: TRUE | AN10: [] | AO10: FALSE | AP10: FALSE | AQ10: PROVINSI
A11: d966a362-1e9b-48a5-a672-c59725728b39 | B11: 28539715-1be1-450e-8d63-2e8ef0dd0596 | C11: ["CAWI"] | D11: 4 | E11: FALSE | F11: NIBmowem1546A | G11: 5 | H11: SUBMITTED RESPONDENT | I11: FALSE | J11: XYZ, PT | K11: Jl. Syekh An Nawawi | M11: rtfanir@gmail.com | O11: 1241234567890 | T11: 2026-05-08T04:19:14.938+00:00 | U11: TRUE | V11: 0 | W11: 0 | X11: 0 | Y11: FALSE | Z11: FALSE | AA11: 0 | AB11: 0 | AC11: TRUE | AD11: rtfanir@gmail.com | AE11: CAWI | AF11: FALSE | AG11: 2026-05-08T08:59:39.246+00:00 | AH11: [] | AI11: [] | AJ11: {"id": "928a6a1c-6a9d-467c-84b7-8807a54f5e68", "groupId": "106eaacb-2e9d-4f2d-b436-9c1abdacd45e", "versionCode": 1.0, "dateCreated": "2025-04-26T17:20:35.115+00:00", "isActive": true, "level1": {"id": "89dde136-a5c9-4325-ab78-2d382087f68e", "fullCode": "36", "code": "36", "name": "BANTEN", "level2": {"id": "928a6a1c-6a9d-467c-84b7-8807a54f5e68", "fullCode": "3673", "code": "73", "name": "SERANG"}}} | AK11: {"id": "106eaacb-2e9d-4f2d-b436-9c1abdacd45e", "levelCount": 2, "smallestRegionLevel": "Kabupaten", "groupName": "MFD Feb25 KABUPATEN", "level": [{"id": 1, "name": "Provinsi"}, {"id": 2, "name": "Kabupaten"}]} | AL11: 1 | AM11: TRUE | AN11: [] | AO11: FALSE | AP11: FALSE | AQ11: PROVINSI
A12: dabe734e-2542-4cd9-a3cb-40a2b5fe900c | B12: 28539715-1be1-450e-8d63-2e8ef0dd0596 | C12: ["CAWI"] | D12: 4 | E12: FALSE | F12: NIBmowm6r05B4 | G12: 0 | H12: DRAFT | I12: FALSE | J12: UNIVERSITAS AL-KHAIRIYAH | K12: JL.H.ENGGUS ARJA NO 1 CILEGON | M12: keufeb2025@gmail.com | T12: 2026-05-08T08:01:48.230+00:00 | U12: TRUE | V12: 0 | W12: 0 | X12: 0 | Y12: FALSE | Z12: FALSE | AA12: 0 | AB12: 0 | AC12: FALSE | AD12: keufeb2025@gmail.com | AE12: CAWI | AF12: FALSE | AG12: 2026-05-08T08:45:24.295+00:00 | AH12: [] | AI12: [] | AJ12: {"id": "a4276ff7-8dfc-4165-8df4-af6422d59ce3", "groupId": "106eaacb-2e9d-4f2d-b436-9c1abdacd45e", "versionCode": 1.0, "dateCreated": "2025-04-26T17:20:35.105+00:00", "isActive": true, "level1": {"id": "89dde136-a5c9-4325-ab78-2d382087f68e", "fullCode": "36", "code": "36", "name": "BANTEN", "level2": {"id": "a4276ff7-8dfc-4165-8df4-af6422d59ce3", "fullCode": "3672", "code": "72", "name": "CILEGON"}}} | AK12: {"id": "106eaacb-2e9d-4f2d-b436-9c1abdacd45e", "levelCount": 2, "smallestRegionLevel": "Kabupaten", "groupName": "MFD Feb25 KABUPATEN", "level": [{"id": 1, "name": "Provinsi"}, {"id": 2, "name": "Kabupaten"}]} | AL12: 1 | AM12: TRUE | AN12: [] | AO12: FALSE | AP12: FALSE | AQ12: PROVINSI
A13: 630c5689-4264-4717-9468-5bc8edc74da8 | B13: 28539715-1be1-450e-8d63-2e8ef0dd0596 | C13: ["CAWI"] | D13: 4 | E13: FALSE | F13: NIBmowm7jCEF2 | G13: 0 | H13: DRAFT | I13: FALSE | J13: Yayasan Islam Syekh-Yusuf | K13: Jl Maulana Yusuf, Kelurahan Babakan, Kecamatan Tangerang, Kota Tangerang | M13: anggi@unis.ac.id | T13: 2026-05-08T07:56:19.263+00:00 | U13: TRUE | V13: 0 | W13: 0 | X13: 0 | Y13: FALSE | Z13: FALSE | AA13: 0 | AB13: 0 | AC13: FALSE | AD13: anggi@unis.ac.id | AE13: CAWI | AF13: FALSE | AG13: 2026-05-08T08:38:58.724+00:00 | AH13: [] | AI13: [] | AJ13: {"id": "bfce7f62-5d5a-4ddb-aa9a-1cc4f918ddf0", "groupId": "106eaacb-2e9d-4f2d-b436-9c1abdacd45e", "versionCode": 1.0, "dateCreated": "2025-04-26T17:20:35.094+00:00", "isActive": true, "level1": {"id": "89dde136-a5c9-4325-ab78-2d382087f68e", "fullCode": "36", "code": "36", "name": "BANTEN", "level2": {"id": "bfce7f62-5d5a-4ddb-aa9a-1cc4f918ddf0", "fullCode": "3671", "code": "71", "name": "TANGERANG"}}} | AK13: {"id": "106eaacb-2e9d-4f2d-b436-9c1abdacd45e", "levelCount": 2, "smallestRegionLevel": "Kabupaten", "groupName": "MFD Feb25 KABUPATEN", "level": [{"id": 1, "name": "Provinsi"}, {"id": 2, "name": "Kabupaten"}]} | AL13: 1 | AM13: TRUE | AN13: [] | AO13: FALSE | AP13: FALSE | AQ13: PROVINSI
A14: 07b64917-8970-4aaa-afcf-d36bd2032848 | B14: 28539715-1be1-450e-8d63-2e8ef0dd0596 | C14: ["CAWI"] | D14: 4 | E14: FALSE | F14: NIBmowm5811C1 | G14: 0 | H14: DRAFT | I14: FALSE | J14: Yayasan Setia Budhi Rangkasbitung | K14: Komplek Pendidikan, Jl Budi Utomo No 22L, Lebak - Banten | M14: humas@usbr.ac.id | T14: 2026-05-08T07:49:58.869+00:00 | U14: TRUE | V14: 0 | W14: 0 | X14: 0 | Y14: FALSE | Z14: FALSE | AA14: 0 | AB14: 0 | AC14: FALSE | AD14: humas@usbr.ac.id | AE14: CAWI | AF14: FALSE | AG14: 2026-05-08T08:37:15.547+00:00 | AH14: [] | AI14: [] | AJ14: {"id": "b76d07d3-6c8d-4155-a3c4-38a079c268ec", "groupId": "106eaacb-2e9d-4f2d-b436-9c1abdacd45e", "versionCode": 1.0, "dateCreated": "2025-04-26T17:20:35.059+00:00", "isActive": true, "level1": {"id": "89dde136-a5c9-4325-ab78-2d382087f68e", "fullCode": "36", "code": "36", "name": "BANTEN", "level2": {"id": "b76d07d3-6c8d-4155-a3c4-38a079c268ec", "fullCode": "3602", "code": "02", "name": "LEBAK"}}} | AK14: {"id": "106eaacb-2e9d-4f2d-b436-9c1abdacd45e", "levelCount": 2, "smallestRegionLevel": "Kabupaten", "groupName": "MFD Feb25 KABUPATEN", "level": [{"id": 1, "name": "Provinsi"}, {"id": 2, "name": "Kabupaten"}]} | AL14: 1 | AM14: TRUE | AN14: [] | AO14: FALSE | AP14: FALSE | AQ14: PROVINSI
A15: 38e23fbb-f66f-4933-bcf1-44ff33d6944a | B15: 28539715-1be1-450e-8d63-2e8ef0dd0596 | C15: ["CAWI"] | D15: 4 | E15: FALSE | F15: NIBmowm6t7C96 | G15: 0 | H15: DRAFT | I15: FALSE | J15: UNIVERSTAS SITUS JAYA BANTEN | K15: Jl. Bhayangkara, Cipocok Jaya, Kota Serang, BANTEN | M15: unsijabanten2025@gmail.com | O15: 5072010 | T15: 2026-05-08T07:54:01.053+00:00 | U15: TRUE | V15: 0 | W15: 0 | X15: 0 | Y15: FALSE | Z15: FALSE | AA15: 0 | AB15: 0 | AC15: FALSE | AD15: unsijabanten2025@gmail.com | AE15: CAWI | AF15: FALSE | AG15: 2026-05-08T08:37:11.418+00:00 | AH15: [] | AI15: [] | AJ15: {"id": "2f16d13b-ee82-4892-942b-5130976b3b4a", "groupId": "106eaacb-2e9d-4f2d-b436-9c1abdacd45e", "versionCode": 1.0, "dateCreated": "2025-04-26T17:20:35.045+00:00", "isActive": true, "level1": {"id": "89dde136-a5c9-4325-ab78-2d382087f68e", "fullCode": "36", "code": "36", "name": "BANTEN", "level2": {"id": "2f16d13b-ee82-4892-942b-5130976b3b4a", "fullCode": "3601", "code": "01", "name": "PANDEGLANG"}}} | AK15: {"id": "106eaacb-2e9d-4f2d-b436-9c1abdacd45e", "levelCount": 2, "smallestRegionLevel": "Kabupaten", "groupName": "MFD Feb25 KABUPATEN", "level": [{"id": 1, "name": "Provinsi"}, {"id": 2, "name": "Kabupaten"}]} | AL15: 1 | AM15: TRUE | AN15: [] | AO15: FALSE | AP15: FALSE | AQ15: PROVINSI
A16: fcbe96de-cccb-4b88-a9a4-0b64c55ce32d | B16: 28539715-1be1-450e-8d63-2e8ef0dd0596 | C16: ["CAWI"] | D16: 4 | E16: FALSE | F16: NIBmowm1b3D97 | G16: 0 | H16: DRAFT | I16: FALSE | J16: Yayasan Andalusia Nusantara Jakarta | K16: JL. KUTAI RAYA NO 1 PERUMNAS III BENCONGAN KELAPA DUA KAB TANGERANG | M16: stikes@andalusia.ac.id | T16: 2026-05-08T07:52:05.837+00:00 | U16: TRUE | V16: 0 | W16: 0 | X16: 0 | Y16: FALSE | Z16: FALSE | AA16: 0 | AB16: 0 | AC16: FALSE | AD16: stikes@andalusia.ac.id | AE16: CAWI | AF16: FALSE | AG16: 2026-05-08T08:36:47.440+00:00 | AH16: [] | AI16: [] | AJ16: {"id": "4dbdaf00-9318-4ea5-91e0-0fb0814f5c04", "groupId": "106eaacb-2e9d-4f2d-b436-9c1abdacd45e", "versionCode": 1.0, "dateCreated": "2025-04-26T17:20:35.071+00:00", "isActive": true, "level1": {"id": "89dde136-a5c9-4325-ab78-2d382087f68e", "fullCode": "36", "code": "36", "name": "BANTEN", "level2": {"id": "4dbdaf00-9318-4ea5-91e0-0fb0814f5c04", "fullCode": "3603", "code": "03", "name": "TANGERANG"}}} | AK16: {"id": "106eaacb-2e9d-4f2d-b436-9c1abdacd45e", "levelCount": 2, "smallestRegionLevel": "Kabupaten", "groupName": "MFD Feb25 KABUPATEN", "level": [{"id": 1, "name": "Provinsi"}, {"id": 2, "name": "Kabupaten"}]} | AL16: 1 | AM16: TRUE | AN16: [] | AO16: FALSE | AP16: FALSE | AQ16: PROVINSI
A17: 62fb1a58-f33d-4adc-8aab-4a36d0af2c01 | B17: 28539715-1be1-450e-8d63-2e8ef0dd0596 | C17: ["CAWI"] | D17: 4 | E17: FALSE | F17: 0233010212626 | G17: 0 | H17: DRAFT | I17: FALSE | J17: POLITEKNIK PGRI BANTEN | K17: Jl raya serang cilegon km 12 desa serdang kec.kramatwatu kab serang | M17: mila@politeknikpgribanten.ac.id | O17: 0233010212626 | T17: 2026-05-08T07:52:47.231+00:00 | U17: TRUE | V17: 0 | W17: 0 | X17: 0 | Y17: FALSE | Z17: FALSE | AA17: 0 | AB17: 0 | AC17: FALSE | AD17: mila@politeknikpgribanten.ac.id | AE17: CAWI | AF17: FALSE | AG17: 2026-05-08T08:32:07.934+00:00 | AH17: [] | AI17: [] | AJ17: {"id": "71723978-814a-463d-a4cd-e1c582fbd163", "groupId": "106eaacb-2e9d-4f2d-b436-9c1abdacd45e", "versionCode": 1.0, "dateCreated": "2025-04-26T17:20:35.082+00:00", "isActive": true, "level1": {"id": "89dde136-a5c9-4325-ab78-2d382087f68e", "fullCode": "36", "code": "36", "name": "BANTEN", "level2": {"id": "71723978-814a-463d-a4cd-e1c582fbd163", "fullCode": "3604", "code": "04", "name": "SERANG"}}} | AK17: {"id": "106eaacb-2e9d-4f2d-b436-9c1abdacd45e", "levelCount": 2, "smallestRegionLevel": "Kabupaten", "groupName": "MFD Feb25 KABUPATEN", "level": [{"id": 1, "name": "Provinsi"}, {"id": 2, "name": "Kabupaten"}]} | AL17: 1 | AM17: TRUE | AN17: [] | AO17: FALSE | AP17: FALSE | AQ17: PROVINSI
A18: 1b3e2710-b65c-4186-a010-d88bc2734a67 | B18: 28539715-1be1-450e-8d63-2e8ef0dd0596 | C18: ["CAWI"] | D18: 4 | E18: FALSE | F18: NIBmowm6pEA16 | G18: 0 | H18: DRAFT | I18: FALSE | J18: STIKES FAATHIR HUSADA | K18: Jl. Rata saga No. 20 Desa Saga Kec Balaraja Kab Tangerang | M18: firazmunafirst3307@gmail.com | O18: 2502250053023 | T18: 2026-05-08T07:55:00.219+00:00 | U18: TRUE | V18: 0 | W18: 0 | X18: 0 | Y18: FALSE | Z18: FALSE | AA18: 0 | AB18: 0 | AC18: FALSE | AD18: firazmunafirst3307@gmail.com | AE18: CAWI | AF18: FALSE | AG18: 2026-05-08T08:30:02.893+00:00 | AH18: [] | AI18: [] | AJ18: {"id": "4dbdaf00-9318-4ea5-91e0-0fb0814f5c04", "groupId": "106eaacb-2e9d-4f2d-b436-9c1abdacd45e", "versionCode": 1.0, "dateCreated": "2025-04-26T17:20:35.071+00:00", "isActive": true, "level1": {"id": "89dde136-a5c9-4325-ab78-2d382087f68e", "fullCode": "36", "code": "36", "name": "BANTEN", "level2": {"id": "4dbdaf00-9318-4ea5-91e0-0fb0814f5c04", "fullCode": "3603", "code": "03", "name": "TANGERANG"}}} | AK18: {"id": "106eaacb-2e9d-4f2d-b436-9c1abdacd45e", "levelCount": 2, "smallestRegionLevel": "Kabupaten", "groupName": "MFD Feb25 KABUPATEN", "level": [{"id": 1, "name": "Provinsi"}, {"id": 2, "name": "Kabupaten"}]} | AL18: 1 | AM18: TRUE | AN18: [] | AO18: FALSE | AP18: FALSE | AQ18: PROVINSI
A19: 404d7d67-ea88-4169-ad3b-5c53b97401eb | B19: 28539715-1be1-450e-8d63-2e8ef0dd0596 | C19: ["CAWI"] | D19: 4 | E19: FALSE | F19: NIBmowmapEEC4 | G19: 0 | H19: DRAFT | I19: FALSE | J19: UNIVERSITAS DHARMA INDONESIA | K19: JL. RAYA SERANG KAM 18,2 SUKANEGARA KEC. CIKUPA TANGERANG BANTEN 15710 | M19: universitasdharmaindonesia@gmail.com | T19: 2026-05-08T07:59:53.663+00:00 | U19: TRUE | V19: 0 | W19: 0 | X19: 0 | Y19: FALSE | Z19: FALSE | AA19: 0 | AB19: 0 | AC19: FALSE | AD19: universitasdharmaindonesia@gmail.com | AE19: CAWI | AF19: FALSE | AG19: 2026-05-08T08:23:25.378+00:00 | AH19: [] | AI19: [] | AJ19: {"id": "4dbdaf00-9318-4ea5-91e0-0fb0814f5c04", "groupId": "106eaacb-2e9d-4f2d-b436-9c1abdacd45e", "versionCode": 1.0, "dateCreated": "2025-04-26T17:20:35.071+00:00", "isActive": true, "level1": {"id": "89dde136-a5c9-4325-ab78-2d382087f68e", "fullCode": "36", "code": "36", "name": "BANTEN", "level2": {"id": "4dbdaf00-9318-4ea5-91e0-0fb0814f5c04", "fullCode": "3603", "code": "03", "name": "TANGERANG"}}} | AK19: {"id": "106eaacb-2e9d-4f2d-b436-9c1abdacd45e", "levelCount": 2, "smallestRegionLevel": "Kabupaten", "groupName": "MFD Feb25 KABUPATEN", "level": [{"id": 1, "name": "Provinsi"}, {"id": 2, "name": "Kabupaten"}]} | AL19: 1 | AM19: TRUE | AN19: [] | AO19: FALSE | AP19: FALSE | AQ19: PROVINSI
A20: 8aa28ec9-94fc-4dbc-b098-d7e16939b990 | B20: 28539715-1be1-450e-8d63-2e8ef0dd0596 | C20: ["CAWI"] | D20: 4 | E20: FALSE | F20: 2110220032153 | G20: 0 | H20: DRAFT | I20: FALSE | J20: YAYASAN INDONESIA SAINS DAN MANAJEMEN JAKARTA | K20: KOMPLEK PERUMAHAN SUDIRMAN INDAH BLOK E, TIGARAKSA, KAB. TANGERANG | M20: info@untara.ac.id | O20: 2110220032153 | T20: 2026-05-08T07:53:11.842+00:00 | U20: TRUE | V20: 0 | W20: 0 | X20: 0 | Y20: FALSE | Z20: FALSE | AA20: 0 | AB20: 0 | AC20: FALSE | AD20: info@untara.ac.id | AE20: CAWI | AF20: FALSE | AG20: 2026-05-08T08:22:37.560+00:00 | AH20: [] | AI20: [] | AJ20: {"id": "4dbdaf00-9318-4ea5-91e0-0fb0814f5c04", "groupId": "106eaacb-2e9d-4f2d-b436-9c1abdacd45e", "versionCode": 1.0, "dateCreated": "2025-04-26T17:20:35.071+00:00", "isActive": true, "level1": {"id": "89dde136-a5c9-4325-ab78-2d382087f68e", "fullCode": "36", "code": "36", "name": "BANTEN", "level2": {"id": "4dbdaf00-9318-4ea5-91e0-0fb0814f5c04", "fullCode": "3603", "code": "03", "name": "TANGERANG"}}} | AK20: {"id": "106eaacb-2e9d-4f2d-b436-9c1abdacd45e", "levelCount": 2, "smallestRegionLevel": "Kabupaten", "groupName": "MFD Feb25 KABUPATEN", "level": [{"id": 1, "name": "Provinsi"}, {"id": 2, "name": "Kabupaten"}]} | AL20: 1 | AM20: TRUE | AN20: [] | AO20: FALSE | AP20: FALSE | AQ20: PROVINSI
A21: f72bf254-12e8-4f55-96e4-5fe28e861083 | B21: 28539715-1be1-450e-8d63-2e8ef0dd0596 | C21: ["CAWI"] | D21: 1 | E21: FALSE | F21: 0259010190342 | G21: 0 | H21: OPEN | I21: FALSE | J21: UNIVERSITAS PRIMAGRAHA | K21: Serang-Banten | T21: 2026-05-08T07:58:34.873+00:00 | U21: TRUE | V21: 0 | W21: 0 | X21: 0 | Y21: FALSE | Z21: FALSE | AC21: FALSE | AD21: ayugebyf@gmail.com | AF21: FALSE | AG21: 2026-05-08T07:58:34.873+00:00 | AH21: [] | AI21: [] | AJ21: {"id": "928a6a1c-6a9d-467c-84b7-8807a54f5e68", "groupId": "106eaacb-2e9d-4f2d-b436-9c1abdacd45e", "versionCode": 1.0, "dateCreated": "2025-04-26T17:20:35.115+00:00", "isActive": true, "level1": {"id": "89dde136-a5c9-4325-ab78-2d382087f68e", "fullCode": "36", "code": "36", "name": "BANTEN", "level2": {"id": "928a6a1c-6a9d-467c-84b7-8807a54f5e68", "fullCode": "3673", "code": "73", "name": "SERANG"}}} | AK21: {"id": "106eaacb-2e9d-4f2d-b436-9c1abdacd45e", "levelCount": 2, "smallestRegionLevel": "Kabupaten", "groupName": "MFD Feb25 KABUPATEN", "level": [{"id": 1, "name": "Provinsi"}, {"id": 2, "name": "Kabupaten"}]} | AL21: 1 | AM21: TRUE | AN21: [] | AO21: FALSE | AP21: FALSE | AQ21: PROVINSI
A22: 2246f50c-820b-4202-8b24-47104e548a57 | B22: 28539715-1be1-450e-8d63-2e8ef0dd0596 | C22: ["CAWI"] | D22: 1 | E22: FALSE | F22: NIBmowm8mC58C | G22: 0 | H22: OPEN | I22: FALSE | J22: SEKOLAH TINGGI ILMU KESEHATAN WIDYA DHARMA HUSADA TANGERANG | K22: JL PAJAJARAN NO 1 PAMULANG BARAT | T22: 2026-05-08T07:54:28.409+00:00 | U22: TRUE | V22: 0 | W22: 0 | X22: 0 | Y22: FALSE | Z22: FALSE | AC22: FALSE | AD22: stikeswdh@gmail.com | AF22: FALSE | AG22: 2026-05-08T07:54:28.409+00:00 | AH22: [] | AI22: [] | AJ22: {"id": "3c7d6867-32a0-4006-9d0a-b8d39ff646d1", "groupId": "106eaacb-2e9d-4f2d-b436-9c1abdacd45e", "versionCode": 1.0, "dateCreated": "2025-04-26T17:20:35.126+00:00", "isActive": true, "level1": {"id": "89dde136-a5c9-4325-ab78-2d382087f68e", "fullCode": "36", "code": "36", "name": "BANTEN", "level2": {"id": "3c7d6867-32a0-4006-9d0a-b8d39ff646d1", "fullCode": "3674", "code": "74", "name": "TANGERANG SELATAN"}}} | AK22: {"id": "106eaacb-2e9d-4f2d-b436-9c1abdacd45e", "levelCount": 2, "smallestRegionLevel": "Kabupaten", "groupName": "MFD Feb25 KABUPATEN", "level": [{"id": 1, "name": "Provinsi"}, {"id": 2, "name": "Kabupaten"}]} | AL22: 1 | AM22: TRUE | AN22: [] | AO22: FALSE | AP22: FALSE | AQ22: PROVINSI
A23: def6ee2c-e9d6-49b4-83fd-3e41991d894a | B23: 28539715-1be1-450e-8d63-2e8ef0dd0596 | C23: ["CAWI"] | D23: 1 | E23: FALSE | F23: NIBmowm1wF166 | G23: 0 | H23: OPEN | I23: FALSE | J23: Universitas Muhammadiyah Tangerang | K23: Jl. Perintis Kemerdekaan I No.33, RT.007/RW.003, Babakan, Cikokol, Kec. Tangerang, Kota Tangerang, Banten 15118 | T23: 2026-05-08T07:53:02.102+00:00 | U23: TRUE | V23: 0 | W23: 0 | X23: 0 | Y23: FALSE | Z23: FALSE | AC23: FALSE | AD23: btsi@umt.ac.id | AF23: FALSE | AG23: 2026-05-08T07:53:02.102+00:00 | AH23: [] | AI23: [] | AJ23: {"id": "4dbdaf00-9318-4ea5-91e0-0fb0814f5c04", "groupId": "106eaacb-2e9d-4f2d-b436-9c1abdacd45e", "versionCode": 1.0, "dateCreated": "2025-04-26T17:20:35.071+00:00", "isActive": true, "level1": {"id": "89dde136-a5c9-4325-ab78-2d382087f68e", "fullCode": "36", "code": "36", "name": "BANTEN", "level2": {"id": "4dbdaf00-9318-4ea5-91e0-0fb0814f5c04", "fullCode": "3603", "code": "03", "name": "TANGERANG"}}} | AK23: {"id": "106eaacb-2e9d-4f2d-b436-9c1abdacd45e", "levelCount": 2, "smallestRegionLevel": "Kabupaten", "groupName": "MFD Feb25 KABUPATEN", "level": [{"id": 1, "name": "Provinsi"}, {"id": 2, "name": "Kabupaten"}]} | AL23: 1 | AM23: TRUE | AN23: [] | AO23: FALSE | AP23: FALSE | AQ23: PROVINSI
A24: ca50d764-b0b1-42e8-a24e-50b51165f2cb | B24: 28539715-1be1-450e-8d63-2e8ef0dd0596 | C24: ["CAWI"] | D24: 1 | E24: FALSE | F24: NIBmowm7b7CAD | G24: 0 | H24: OPEN | I24: FALSE | J24: POLITEKNIK KESEHATAN AISYIYAH BANTEN | K24: JL.RAYA CILEGON KM 8 KRAMATWATU | T24: 2026-05-08T07:52:07.429+00:00 | U24: TRUE | V24: 0 | W24: 0 | X24: 0 | Y24: FALSE | Z24: FALSE | AC24: FALSE | AD24: devie@polisa.ac.id | AF24: FALSE | AG24: 2026-05-08T07:52:07.429+00:00 | AH24: [] | AI24: [] | AJ24: {"id": "71723978-814a-463d-a4cd-e1c582fbd163", "groupId": "106eaacb-2e9d-4f2d-b436-9c1abdacd45e", "versionCode": 1.0, "dateCreated": "2025-04-26T17:20:35.082+00:00", "isActive": true, "level1": {"id": "89dde136-a5c9-4325-ab78-2d382087f68e", "fullCode": "36", "code": "36", "name": "BANTEN", "level2": {"id": "71723978-814a-463d-a4cd-e1c582fbd163", "fullCode": "3604", "code": "04", "name": "SERANG"}}} | AK24: {"id": "106eaacb-2e9d-4f2d-b436-9c1abdacd45e", "levelCount": 2, "smallestRegionLevel": "Kabupaten", "groupName": "MFD Feb25 KABUPATEN", "level": [{"id": 1, "name": "Provinsi"}, {"id": 2, "name": "Kabupaten"}]} | AL24: 1 | AM24: TRUE | AN24: [] | AO24: FALSE | AP24: FALSE | AQ24: PROVINSI
A25: 2ec1ac09-2a66-4546-ab91-40781bc3269c | B25: 28539715-1be1-450e-8d63-2e8ef0dd0596 | C25: ["CAWI"] | D25: 1 | E25: FALSE | F25: NIBmowm6wDBBE | G25: 0 | H25: OPEN | I25: FALSE | J25: UNIVERSITAS PRIMAGRAHA | K25: Serang-Banten | T25: 2026-05-08T07:51:25.261+00:00 | U25: TRUE | V25: 0 | W25: 0 | X25: 0 | Y25: FALSE | Z25: FALSE | AC25: FALSE | AD25: ayugebyf@gmail.com | AF25: FALSE | AG25: 2026-05-08T07:51:25.261+00:00 | AH25: [] | AI25: [] | AJ25: {"id": "928a6a1c-6a9d-467c-84b7-8807a54f5e68", "groupId": "106eaacb-2e9d-4f2d-b436-9c1abdacd45e", "versionCode": 1.0, "dateCreated": "2025-04-26T17:20:35.115+00:00", "isActive": true, "level1": {"id": "89dde136-a5c9-4325-ab78-2d382087f68e", "fullCode": "36", "code": "36", "name": "BANTEN", "level2": {"id": "928a6a1c-6a9d-467c-84b7-8807a54f5e68", "fullCode": "3673", "code": "73", "name": "SERANG"}}} | AK25: {"id": "106eaacb-2e9d-4f2d-b436-9c1abdacd45e", "levelCount": 2, "smallestRegionLevel": "Kabupaten", "groupName": "MFD Feb25 KABUPATEN", "level": [{"id": 1, "name": "Provinsi"}, {"id": 2, "name": "Kabupaten"}]} | AL25: 1 | AM25: TRUE | AN25: [] | AO25: FALSE | AP25: FALSE | AQ25: PROVINSI
A26: e491b94b-bcf6-4781-b85a-9349b44d2673 | B26: 28539715-1be1-450e-8d63-2e8ef0dd0596 | C26: ["CAWI"] | D26: 1 | E26: FALSE | F26: NIBmowm6m5B27 | G26: 0 | H26: OPEN | I26: FALSE | J26: Universitas Matana | K26: Matana University Tower, Jl. CBD Barat Kav Jl. CBD Barat No.1 Lt P3, RW.1, Curug Sangereng, Kec. Klp. Dua, Kabupaten Tangerang, Banten 15810 | T26: 2026-05-08T07:51:13.247+00:00 | U26: TRUE | V26: 0 | W26: 0 | X26: 0 | Y26: FALSE | Z26: FALSE | AC26: FALSE | AD26: LPM@matanauniversity.ac.id | AF26: FALSE | AG26: 2026-05-08T07:51:13.247+00:00 | AH26: [] | AI26: [] | AJ26: {"id": "4dbdaf00-9318-4ea5-91e0-0fb0814f5c04", "groupId": "106eaacb-2e9d-4f2d-b436-9c1abdacd45e", "versionCode": 1.0, "dateCreated": "2025-04-26T17:20:35.071+00:00", "isActive": true, "level1": {"id": "89dde136-a5c9-4325-ab78-2d382087f68e", "fullCode": "36", "code": "36", "name": "BANTEN", "level2": {"id": "4dbdaf00-9318-4ea5-91e0-0fb0814f5c04", "fullCode": "3603", "code": "03", "name": "TANGERANG"}}} | AK26: {"id": "106eaacb-2e9d-4f2d-b436-9c1abdacd45e", "levelCount": 2, "smallestRegionLevel": "Kabupaten", "groupName": "MFD Feb25 KABUPATEN", "level": [{"id": 1, "name": "Provinsi"}, {"id": 2, "name": "Kabupaten"}]} | AL26: 1 | AM26: TRUE | AN26: [] | AO26: FALSE | AP26: FALSE | AQ26: PROVINSI
A27: a24fde0f-d132-41ff-b361-8e148c5d9f33 | B27: 28539715-1be1-450e-8d63-2e8ef0dd0596 | C27: ["CAWI"] | D27: 4 | E27: FALSE | F27: NIBmov5t3ACB4 | G27: 5 | H27: SUBMITTED RESPONDENT | I27: FALSE | J27: Gopur Family | K27: Asrama Polisi Batu Ceper | M27: bewokreyang67@gmail.com | T27: 2026-05-07T07:24:19.054+00:00 | U27: TRUE | V27: 0 | W27: 0 | X27: 0 | Y27: FALSE | Z27: FALSE | AA27: 0 | AB27: 0 | AC27: TRUE | AD27: bewokreyang67@gmail.com | AE27: CAWI | AF27: FALSE | AG27: 2026-05-07T07:57:23.567+00:00 | AH27: [] | AI27: [] | AJ27: {"id": "bfce7f62-5d5a-4ddb-aa9a-1cc4f918ddf0", "groupId": "106eaacb-2e9d-4f2d-b436-9c1abdacd45e", "versionCode": 1.0, "dateCreated": "2025-04-26T17:20:35.094+00:00", "isActive": true, "level1": {"id": "89dde136-a5c9-4325-ab78-2d382087f68e", "fullCode": "36", "code": "36", "name": "BANTEN", "level2": {"id": "bfce7f62-5d5a-4ddb-aa9a-1cc4f918ddf0", "fullCode": "3671", "code": "71", "name": "TANGERANG"}}} | AK27: {"id": "106eaacb-2e9d-4f2d-b436-9c1abdacd45e", "levelCount": 2, "smallestRegionLevel": "Kabupaten", "groupName": "MFD Feb25 KABUPATEN", "level": [{"id": 1, "name": "Provinsi"}, {"id": 2, "name": "Kabupaten"}]} | AL27: 1 | AM27: TRUE | AN27: [] | AO27: FALSE | AP27: FALSE | AQ27: PROVINSI
A28: 59917947-829c-486c-8604-736e76669fe0 | B28: 28539715-1be1-450e-8d63-2e8ef0dd0596 | C28: ["CAWI"] | D28: 4 | E28: FALSE | F28: NIBmov59lCDE3 | G28: 0 | H28: DRAFT | I28: FALSE | J28: Fahri ayam sipon | K28: Kp. Gunung kel. Cipondoh kec. Cipondoh kota Tangerang | M28: rojidiana15@gmail.com | T28: 2026-05-07T07:13:57.128+00:00 | U28: TRUE | V28: 0 | W28: 0 | X28: 0 | Y28: FALSE | Z28: FALSE | AA28: 0 | AB28: 0 | AC28: FALSE | AD28: rojidiana15@gmail.com | AE28: CAWI | AF28: FALSE | AG28: 2026-05-07T07:56:25.905+00:00 | AH28: [] | AI28: [] | AJ28: {"id": "bfce7f62-5d5a-4ddb-aa9a-1cc4f918ddf0", "groupId": "106eaacb-2e9d-4f2d-b436-9c1abdacd45e", "versionCode": 1.0, "dateCreated": "2025-04-26T17:20:35.094+00:00", "isActive": true, "level1": {"id": "89dde136-a5c9-4325-ab78-2d382087f68e", "fullCode": "36", "code": "36", "name": "BANTEN", "level2": {"id": "bfce7f62-5d5a-4ddb-aa9a-1cc4f918ddf0", "fullCode": "3671", "code": "71", "name": "TANGERANG"}}} | AK28: {"id": "106eaacb-2e9d-4f2d-b436-9c1abdacd45e", "levelCount": 2, "smallestRegionLevel": "Kabupaten", "groupName": "MFD Feb25 KABUPATEN", "level": [{"id": 1, "name": "Provinsi"}, {"id": 2, "name": "Kabupaten"}]} | AL28: 1 | AM28: TRUE | AN28: [] | AO28: FALSE | AP28: FALSE | AQ28: PROVINSI
A29: e754cb3e-9bb1-48a1-856e-25bf927e6983 | B29: 28539715-1be1-450e-8d63-2e8ef0dd0596 | C29: ["CAWI"] | D29: 4 | E29: FALSE | F29: NIBmov5aa90F6 | G29: 5 | H29: SUBMITTED RESPONDENT | I29: FALSE | J29: Koperasi Sekar Tani Sajiva | K29: Jln flamboyan 1 blok b2 no 32 bugel mas indah | M29: sekartanisajiva@gmail.com | T29: 2026-05-07T07:15:24.374+00:00 | U29: TRUE | V29: 0 | W29: 0 | X29: 0 | Y29: FALSE | Z29: FALSE | AA29: 0 | AB29: 0 | AC29: TRUE | AD29: sekartanisajiva@gmail.com | AE29: CAWI | AF29: FALSE | AG29: 2026-05-07T07:50:01.324+00:00 | AH29: [] | AI29: [] | AJ29: {"id": "bfce7f62-5d5a-4ddb-aa9a-1cc4f918ddf0", "groupId": "106eaacb-2e9d-4f2d-b436-9c1abdacd45e", "versionCode": 1.0, "dateCreated": "2025-04-26T17:20:35.094+00:00", "isActive": true, "level1": {"id": "89dde136-a5c9-4325-ab78-2d382087f68e", "fullCode": "36", "code": "36", "name": "BANTEN", "level2": {"id": "bfce7f62-5d5a-4ddb-aa9a-1cc4f918ddf0", "fullCode": "3671", "code": "71", "name": "TANGERANG"}}} | AK29: {"id": "106eaacb-2e9d-4f2d-b436-9c1abdacd45e", "levelCount": 2, "smallestRegionLevel": "Kabupaten", "groupName": "MFD Feb25 KABUPATEN", "level": [{"id": 1, "name": "Provinsi"}, {"id": 2, "name": "Kabupaten"}]} | AL29: 1 | AM29: TRUE | AN29: [] | AO29: FALSE | AP29: FALSE | AQ29: PROVINSI
A30: fd65d609-7497-44d3-8b8c-7eee10683a68 | B30: 28539715-1be1-450e-8d63-2e8ef0dd0596 | C30: ["CAWI"] | D30: 4 | E30: FALSE | F30: NIBmov5678120 | G30: 5 | H30: SUBMITTED RESPONDENT | I30: FALSE | J30: Forum KWT Kota Tangerang | K30: Mina raya 2 blok j5 no 37 villa ilhami Islamic village tangerang 15139 | M30: forumkwtkotatangerang@gmail.com | T30: 2026-05-07T07:09:20.757+00:00 | U30: TRUE | V30: 0 | W30: 0 | X30: 0 | Y30: FALSE | Z30: FALSE | AA30: 0 | AB30: 0 | AC30: TRUE | AD30: forumkwtkotatangerang@gmail.com | AE30: CAWI | AF30: FALSE | AG30: 2026-05-07T07:44:13.435+00:00 | AH30: [] | AI30: [] | AJ30: {"id": "bfce7f62-5d5a-4ddb-aa9a-1cc4f918ddf0", "groupId": "106eaacb-2e9d-4f2d-b436-9c1abdacd45e", "versionCode": 1.0, "dateCreated": "2025-04-26T17:20:35.094+00:00", "isActive": true, "level1": {"id": "89dde136-a5c9-4325-ab78-2d382087f68e", "fullCode": "36", "code": "36", "name": "BANTEN", "level2": {"id": "bfce7f62-5d5a-4ddb-aa9a-1cc4f918ddf0", "fullCode": "3671", "code": "71", "name": "TANGERANG"}}} | AK30: {"id": "106eaacb-2e9d-4f2d-b436-9c1abdacd45e", "levelCount": 2, "smallestRegionLevel": "Kabupaten", "groupName": "MFD Feb25 KABUPATEN", "level": [{"id": 1, "name": "Provinsi"}, {"id": 2, "name": "Kabupaten"}]} | AL30: 1 | AM30: TRUE | AN30: [] | AO30: FALSE | AP30: FALSE | AQ30: PROVINSI
A31: 821f74e9-5e0e-4980-af93-4b64016dd04d | B31: 28539715-1be1-450e-8d63-2e8ef0dd0596 | C31: ["CAWI"] | D31: 4 | E31: FALSE | F31: NIBmov58o787C | G31: 5 | H31: SUBMITTED RESPONDENT | I31: FALSE | J31: Bintang Binar abadi | K31: Jl. H udin gg. Pembangunan 1 rt.04 rw.05 kec.cipondoh kel. Poris plawad utara | M31: jafis08@gmail.com | O31: 0702220041667 | T31: 2026-05-07T07:09:41.484+00:00 | U31: TRUE | V31: 0 | W31: 0 | X31: 0 | Y31: FALSE | Z31: FALSE | AA31: 0 | AB31: 0 | AC31: TRUE | AD31: jafis08@gmail.com | AE31: CAWI | AF31: FALSE | AG31: 2026-05-07T07:39:37.476+00:00 | AH31: [] | AI31: [] | AJ31: {"id": "bfce7f62-5d5a-4ddb-aa9a-1cc4f918ddf0", "groupId": "106eaacb-2e9d-4f2d-b436-9c1abdacd45e", "versionCode": 1.0, "dateCreated": "2025-04-26T17:20:35.094+00:00", "isActive": true, "level1": {"id": "89dde136-a5c9-4325-ab78-2d382087f68e", "fullCode": "36", "code": "36", "name": "BANTEN", "level2": {"id": "bfce7f62-5d5a-4ddb-aa9a-1cc4f918ddf0", "fullCode": "3671", "code": "71", "name": "TANGERANG"}}} | AK31: {"id": "106eaacb-2e9d-4f2d-b436-9c1abdacd45e", "levelCount": 2, "smallestRegionLevel": "Kabupaten", "groupName": "MFD Feb25 KABUPATEN", "level": [{"id": 1, "name": "Provinsi"}, {"id": 2, "name": "Kabupaten"}]} | AL31: 1 | AM31: TRUE | AN31: [] | AO31: FALSE | AP31: FALSE | AQ31: PROVINSI
A32: d361f194-af62-413e-875e-6eb0c85eb25c | B32: 28539715-1be1-450e-8d63-2e8ef0dd0596 | C32: ["CAWI"] | D32: 1 | E32: FALSE | F32: NIBmov67eE637 | G32: 0 | H32: OPEN | I32: FALSE | J32: Koptan Gofur family | K32: Jl Aspol batuceper | T32: 2026-05-07T07:37:25.703+00:00 | U32: TRUE | V32: 0 | W32: 0 | X32: 0 | Y32: FALSE | Z32: FALSE | AC32: FALSE | AD32: bewokreyang67@gmail.com | AF32: FALSE | AG32: 2026-05-07T07:37:25.703+00:00 | AH32: [] | AI32: [] | AJ32: {"id": "bfce7f62-5d5a-4ddb-aa9a-1cc4f918ddf0", "groupId": "106eaacb-2e9d-4f2d-b436-9c1abdacd45e", "versionCode": 1.0, "dateCreated": "2025-04-26T17:20:35.094+00:00", "isActive": true, "level1": {"id": "89dde136-a5c9-4325-ab78-2d382087f68e", "fullCode": "36", "code": "36", "name": "BANTEN", "level2": {"id": "bfce7f62-5d5a-4ddb-aa9a-1cc4f918ddf0", "fullCode": "3671", "code": "71", "name": "TANGERANG"}}} | AK32: {"id": "106eaacb-2e9d-4f2d-b436-9c1abdacd45e", "levelCount": 2, "smallestRegionLevel": "Kabupaten", "groupName": "MFD Feb25 KABUPATEN", "level": [{"id": 1, "name": "Provinsi"}, {"id": 2, "name": "Kabupaten"}]} | AL32: 1 | AM32: TRUE | AN32: [] | AO32: FALSE | AP32: FALSE | AQ32: PROVINSI
A33: 5ac9412a-3652-439f-b71f-cb32a428605a | B33: 28539715-1be1-450e-8d63-2e8ef0dd0596 | C33: ["CAWI"] | D33: 1 | E33: FALSE | F33: NIBmov5ud607F | G33: 0 | H33: OPEN | I33: FALSE | J33: Poktan gopur family | K33: Jl Aspol batuceper | T33: 2026-05-07T07:32:30.906+00:00 | U33: TRUE | V33: 0 | W33: 0 | X33: 0 | Y33: FALSE | Z33: FALSE | AC33: FALSE | AD33: bewokreyang67@gmail.com | AF33: FALSE | AG33: 2026-05-07T07:32:30.906+00:00 | AH33: [] | AI33: [] | AJ33: {"id": "bfce7f62-5d5a-4ddb-aa9a-1cc4f918ddf0", "groupId": "106eaacb-2e9d-4f2d-b436-9c1abdacd45e", "versionCode": 1.0, "dateCreated": "2025-04-26T17:20:35.094+00:00", "isActive": true, "level1": {"id": "89dde136-a5c9-4325-ab78-2d382087f68e", "fullCode": "36", "code": "36", "name": "BANTEN", "level2": {"id": "bfce7f62-5d5a-4ddb-aa9a-1cc4f918ddf0", "fullCode": "3671", "code": "71", "name": "TANGERANG"}}} | AK33: {"id": "106eaacb-2e9d-4f2d-b436-9c1abdacd45e", "levelCount": 2, "smallestRegionLevel": "Kabupaten", "groupName": "MFD Feb25 KABUPATEN", "level": [{"id": 1, "name": "Provinsi"}, {"id": 2, "name": "Kabupaten"}]} | AL33: 1 | AM33: TRUE | AN33: [] | AO33: FALSE | AP33: FALSE | AQ33: PROVINSI
A34: 5f9a8987-1ff8-4ce4-b60c-2bfc572d01cb | B34: 28539715-1be1-450e-8d63-2e8ef0dd0596 | C34: ["CAWI"] | D34: 1 | E34: FALSE | F34: NIBmov5nwB33C | G34: 0 | H34: OPEN | I34: FALSE | J34: Gopur Family | K34: Asrama Polisi Batu Ceper | T34: 2026-05-07T07:20:55.453+00:00 | U34: TRUE | V34: 0 | W34: 0 | X34: 0 | Y34: FALSE | Z34: FALSE | AC34: FALSE | AD34: brewokrewang67@gmail.com | AF34: FALSE | AG34: 2026-05-07T07:20:55.453+00:00 | AH34: [] | AI34: [] | AJ34: {"id": "bfce7f62-5d5a-4ddb-aa9a-1cc4f918ddf0", "groupId": "106eaacb-2e9d-4f2d-b436-9c1abdacd45e", "versionCode": 1.0, "dateCreated": "2025-04-26T17:20:35.094+00:00", "isActive": true, "level1": {"id": "89dde136-a5c9-4325-ab78-2d382087f68e", "fullCode": "36", "code": "36", "name": "BANTEN", "level2": {"id": "bfce7f62-5d5a-4ddb-aa9a-1cc4f918ddf0", "fullCode": "3671", "code": "71", "name": "TANGERANG"}}} | AK34: {"id": "106eaacb-2e9d-4f2d-b436-9c1abdacd45e", "levelCount": 2, "smallestRegionLevel": "Kabupaten", "groupName": "MFD Feb25 KABUPATEN", "level": [{"id": 1, "name": "Provinsi"}, {"id": 2, "name": "Kabupaten"}]} | AL34: 1 | AM34: TRUE | AN34: [] | AO34: FALSE | AP34: FALSE | AQ34: PROVINSI
A35: 5c65e463-62e8-4552-8e71-976526812e36 | B35: 28539715-1be1-450e-8d63-2e8ef0dd0596 | C35: ["CAWI"] | D35: 1 | E35: FALSE | F35: NIBmov5di17BE | G35: 0 | H35: OPEN | I35: FALSE | J35: Gopur Family | K35: Asrama Polisi Batu Ceper | T35: 2026-05-07T07:17:23.156+00:00 | U35: TRUE | V35: 0 | W35: 0 | X35: 0 | Y35: FALSE | Z35: FALSE | AC35: FALSE | AD35: bewokreyang67@gmail.com | AF35: FALSE | AG35: 2026-05-07T07:17:23.156+00:00 | AH35: [] | AI35: [] | AJ35: {"id": "bfce7f62-5d5a-4ddb-aa9a-1cc4f918ddf0", "groupId": "106eaacb-2e9d-4f2d-b436-9c1abdacd45e", "versionCode": 1.0, "dateCreated": "2025-04-26T17:20:35.094+00:00", "isActive": true, "level1": {"id": "89dde136-a5c9-4325-ab78-2d382087f68e", "fullCode": "36", "code": "36", "name": "BANTEN", "level2": {"id": "bfce7f62-5d5a-4ddb-aa9a-1cc4f918ddf0", "fullCode": "3671", "code": "71", "name": "TANGERANG"}}} | AK35: {"id": "106eaacb-2e9d-4f2d-b436-9c1abdacd45e", "levelCount": 2, "smallestRegionLevel": "Kabupaten", "groupName": "MFD Feb25 KABUPATEN", "level": [{"id": 1, "name": "Provinsi"}, {"id": 2, "name": "Kabupaten"}]} | AL35: 1 | AM35: TRUE | AN35: [] | AO35: FALSE | AP35: FALSE | AQ35: PROVINSI
A36: 5109e285-545e-4902-8d9a-fc9f0a43f4f9 | B36: 28539715-1be1-450e-8d63-2e8ef0dd0596 | C36: ["CAWI"] | D36: 1 | E36: FALSE | F36: NIBmov57z8787 | G36: 0 | H36: OPEN | I36: FALSE | J36: Cihuy Lho | K36: Jl Imam Bonjol | T36: 2026-05-07T07:14:03.027+00:00 | U36: TRUE | V36: 0 | W36: 0 | X36: 0 | Y36: FALSE | Z36: FALSE | AC36: FALSE | AD36: susyucihuy@gmail.com | AF36: FALSE | AG36: 2026-05-07T07:14:03.027+00:00 | AH36: [] | AI36: [] | AJ36: {"id": "bfce7f62-5d5a-4ddb-aa9a-1cc4f918ddf0", "groupId": "106eaacb-2e9d-4f2d-b436-9c1abdacd45e", "versionCode": 1.0, "dateCreated": "2025-04-26T17:20:35.094+00:00", "isActive": true, "level1": {"id": "89dde136-a5c9-4325-ab78-2d382087f68e", "fullCode": "36", "code": "36", "name": "BANTEN", "level2": {"id": "bfce7f62-5d5a-4ddb-aa9a-1cc4f918ddf0", "fullCode": "3671", "code": "71", "name": "TANGERANG"}}} | AK36: {"id": "106eaacb-2e9d-4f2d-b436-9c1abdacd45e", "levelCount": 2, "smallestRegionLevel": "Kabupaten", "groupName": "MFD Feb25 KABUPATEN", "level": [{"id": 1, "name": "Provinsi"}, {"id": 2, "name": "Kabupaten"}]} | AL36: 1 | AM36: TRUE | AN36: [] | AO36: FALSE | AP36: FALSE | AQ36: PROVINSI
A37: 61c123e0-770c-47a5-b644-eb4b07b9708f | B37: 28539715-1be1-450e-8d63-2e8ef0dd0596 | C37: ["CAWI"] | D37: 4 | E37: FALSE | F37: 3671 | G37: 5 | H37: SUBMITTED RESPONDENT | I37: FALSE | J37: TOINGAH | K37: JL. GEMPOL RAYA KUNCIRAN RT 04/ RW 01 NO.13. | M37: toingah26@gmail.com | O37: 2401220047324 | T37: 2026-05-05T13:19:31.328+00:00 | U37: TRUE | V37: 0 | W37: 0 | X37: 0 | Y37: FALSE | Z37: FALSE | AA37: 0 | AB37: 0 | AC37: TRUE | AD37: toingah26@gmail.com | AE37: U-CAWI | AF37: FALSE | AG37: 2026-05-07T05:00:56.361+00:00 | AH37: [] | AI37: [] | AJ37: {"id": "bfce7f62-5d5a-4ddb-aa9a-1cc4f918ddf0", "groupId": "106eaacb-2e9d-4f2d-b436-9c1abdacd45e", "versionCode": 1.0, "dateCreated": "2025-04-26T17:20:35.094+00:00", "isActive": true, "level1": {"id": "89dde136-a5c9-4325-ab78-2d382087f68e", "fullCode": "36", "code": "36", "name": "BANTEN", "level2": {"id": "bfce7f62-5d5a-4ddb-aa9a-1cc4f918ddf0", "fullCode": "3671", "code": "71", "name": "TANGERANG"}}} | AK37: {"id": "106eaacb-2e9d-4f2d-b436-9c1abdacd45e", "levelCount": 2, "smallestRegionLevel": "Kabupaten", "groupName": "MFD Feb25 KABUPATEN", "level": [{"id": 1, "name": "Provinsi"}, {"id": 2, "name": "Kabupaten"}]} | AL37: 1 | AM37: TRUE | AN37: [] | AO37: FALSE | AP37: FALSE | AQ37: PROVINSI
A38: 9b0d0bd4-9f89-460f-80fd-9698387aa8bf | B38: 28539715-1be1-450e-8d63-2e8ef0dd0596 | C38: ["CAWI"] | D38: 4 | E38: FALSE | F38: 8120118051693 | G38: 5 | H38: SUBMITTED RESPONDENT | I38: FALSE | J38: Kspps Benteng Mikro Indonesia | K38: Ruko The Time Square Jl. Boulevard Andalucia Paramount Land Tangerang | M38: yanitanurmala89@gmail.com | O38: 8120118051693 | T38: 2026-05-07T03:55:58.996+00:00 | U38: TRUE | V38: 0 | W38: 0 | X38: 0 | Y38: FALSE | Z38: FALSE | AA38: 0 | AB38: 0 | AC38: TRUE | AD38: yanitanurmala89@gmail.com | AE38: CAWI | AF38: FALSE | AG38: 2026-05-07T04:34:21.603+00:00 | AH38: [] | AI38: [] | AJ38: {"id": "4dbdaf00-9318-4ea5-91e0-0fb0814f5c04", "groupId": "106eaacb-2e9d-4f2d-b436-9c1abdacd45e", "versionCode": 1.0, "dateCreated": "2025-04-26T17:20:35.071+00:00", "isActive": true, "level1": {"id": "89dde136-a5c9-4325-ab78-2d382087f68e", "fullCode": "36", "code": "36", "name": "BANTEN", "level2": {"id": "4dbdaf00-9318-4ea5-91e0-0fb0814f5c04", "fullCode": "3603", "code": "03", "name": "TANGERANG"}}} | AK38: {"id": "106eaacb-2e9d-4f2d-b436-9c1abdacd45e", "levelCount": 2, "smallestRegionLevel": "Kabupaten", "groupName": "MFD Feb25 KABUPATEN", "level": [{"id": 1, "name": "Provinsi"}, {"id": 2, "name": "Kabupaten"}]} | AL38: 1 | AM38: TRUE | AN38: [] | AO38: FALSE | AP38: FALSE | AQ38: PROVINSI
A39: 1c41dcb9-6538-4414-a4bc-ea76accbc821 | B39: 28539715-1be1-450e-8d63-2e8ef0dd0596 | C39: ["CAWI"] | D39: 4 | E39: FALSE | F39: NIBmouy59F48D | G39: 0 | H39: DRAFT | I39: FALSE | J39: Pegadaian, PT | K39: Jl. A. Damjati No 7, Kota Tangerang | M39: donna.almira@pegadaian.co.id | T39: 2026-05-07T03:53:34.958+00:00 | U39: TRUE | V39: 0 | W39: 0 | X39: 0 | Y39: FALSE | Z39: FALSE | AA39: 0 | AB39: 0 | AC39: FALSE | AD39: donna.almira@pegadaian.co.id | AE39: CAWI | AF39: FALSE | AG39: 2026-05-07T04:25:57.635+00:00 | AH39: [] | AI39: [] | AJ39: {"id": "4dbdaf00-9318-4ea5-91e0-0fb0814f5c04", "groupId": "106eaacb-2e9d-4f2d-b436-9c1abdacd45e", "versionCode": 1.0, "dateCreated": "2025-04-26T17:20:35.071+00:00", "isActive": true, "level1": {"id": "89dde136-a5c9-4325-ab78-2d382087f68e", "fullCode": "36", "code": "36", "name": "BANTEN", "level2": {"id": "4dbdaf00-9318-4ea5-91e0-0fb0814f5c04", "fullCode": "3603", "code": "03", "name": "TANGERANG"}}} | AK39: {"id": "106eaacb-2e9d-4f2d-b436-9c1abdacd45e", "levelCount": 2, "smallestRegionLevel": "Kabupaten", "groupName": "MFD Feb25 KABUPATEN", "level": [{"id": 1, "name": "Provinsi"}, {"id": 2, "name": "Kabupaten"}]} | AL39: 1 | AM39: TRUE | AN39: [] | AO39: FALSE | AP39: FALSE | AQ39: PROVINSI
A40: 4448f36d-aa0f-4241-a512-f41867f23969 | B40: 28539715-1be1-450e-8d63-2e8ef0dd0596 | C40: ["CAWI"] | D40: 1 | E40: FALSE | F40: NIBmouz436D69 | G40: 0 | H40: OPEN | I40: FALSE | J40: Ksp mitra dhuafa | K40: Kp.cangkudu,ds.kubang,kec.sukamulya,kab.tangerang | T40: 2026-05-07T04:17:17.317+00:00 | U40: TRUE | V40: 0 | W40: 0 | X40: 0 | Y40: FALSE | Z40: FALSE | AC40: FALSE | AD40: elandwirustandi89@gmail.com | AF40: FALSE | AG40: 2026-05-07T04:17:17.317+00:00 | AH40: [] | AI40: [] | AJ40: {"id": "4dbdaf00-9318-4ea5-91e0-0fb0814f5c04", "groupId": "106eaacb-2e9d-4f2d-b436-9c1abdacd45e", "versionCode": 1.0, "dateCreated": "2025-04-26T17:20:35.071+00:00", "isActive": true, "level1": {"id": "89dde136-a5c9-4325-ab78-2d382087f68e", "fullCode": "36", "code": "36", "name": "BANTEN", "level2": {"id": "4dbdaf00-9318-4ea5-91e0-0fb0814f5c04", "fullCode": "3603", "code": "03", "name": "TANGERANG"}}} | AK40: {"id": "106eaacb-2e9d-4f2d-b436-9c1abdacd45e", "levelCount": 2, "smallestRegionLevel": "Kabupaten", "groupName": "MFD Feb25 KABUPATEN", "level": [{"id": 1, "name": "Provinsi"}, {"id": 2, "name": "Kabupaten"}]} | AL40: 1 | AM40: TRUE | AN40: [] | AO40: FALSE | AP40: FALSE | AQ40: PROVINSI
...

Sheet target
A1: Column1 | B1: Nama | C1: NIB | D1: email
A2: 1 | B2: Dewan Kerajinan Nasional-Daerah Banten (Dekranas-da Banten) | D2: regarbanten1971@gmail.com
A3: 2 | B3: Kamar Dagang Indonesia-Banten (KADIN Banten) | D3: kadinbanten@gmail.com
A4: 3 | B4: Gabungan Pengusaha Konstruksi Indonesia- Banten (Gapensi Banten) | D4: gapensibanten28@gmail.com
A5: 4 | B5: Himpunan Wiraswasta Nasional Minyak dan Gas - Banten (Hiswana Migas Banten)
A6: 5 | B6: Persatuan Radio Siaran Swasta Nasional Indonesia - Banten (PRSSNI Banten)
A7: 6 | B7: Dewan Koperasi Indonesia - Banten (Dekopin Banten)
A8: 7 | B8: Pengusaha Indonesia (Apindo)-Banten
A9: 8 | B9: PT Banten West Java Tourism Development (Pengelola Kawasan Ekonomi Khusus (KEK) Tanjung Lesung) | D9: Bantenwestjava@gmail.com
A10: 9 | B10: PT. Mitratangerang Bhumimas (Pengelola Kawasan Industri & Pergudangan Cikupamas) | D10: lingkungan@multisatuutama.com
A11: 10 | B11: PT. Griya Tirta Asri (Pengelola Kawasan Griya Idola Industrial Park) | D11: agung@gta.barito.co.id
A12: 11 | B12: PT. Blessindo Intiland (Pengelola Kawasan Industri Blessindo) | D12: audrea.ddjo@gmail.com dan linda_bil@yahoo.com
A13: 12 | B13: PT. Putera Daya Perkasa (Pengelola Kawasan Industri Pasar Kemis) | D13: puteradayaperkasa1980@gmail.com
A14: 13 | B14: PT. Nuraiti Tjermin (Pengelola Kawasan Industri Royal Kosambi) | D14: pergudanganroyalkosambi@gmail.com
A15: 14 | B15: PT. Irama Gemilang Lestari (Pengelola Kawasan Industri Sumber Rezeki) | D15: pt.iramagemilanglestari@gmail.com
A16: 15 | B16: PT. Angkasa Pancabersaudara (Pengelola Kawasan Pergudangan Dan Industri Kosambi Permai) | D16: pergudanganroyalkosambi@gmail.com
A17: 16 | B17: PT. Astasiti Mahadhana (Pengelola Kawasan Taman Industri Busan (KIKM)) | D17: astasiti.mahadhana@gmail.com
A18: 17 | B18: PT. Bangun Laksana Persada (Pengelola Kawasan Laksana Business Park) | D18: harianto.widjaja@agungintiland.com
A19: 18 | B19: PT. Bumi Citra Permai (Pengelola Kawasan Millenium Industrial Estate) | D19: ahmadsyaepudin99@gmail.com
A20: 19 | B20: PT. Surya Inter Wisesa (Pengelola Kawasan Ekonomi Khusus Pendidikan, Teknologi, Dan Kesehatan Internasional Banten) | D20: admin.kek@sinarmasland.com
... A25: 24 | B25: PT. Pancapuri Indoperkasa (Kawasan Industri Pancapuri) | D25: pmi.priana1462@gmail.com
A26: 25 | B26: PT. Krakatau Sarana Infrastruktur (Pengelola Kawasan Krakatau Industrial Estate Cilegon)
A27: 26 | B27: PT. Bumi Serpong Damai (Pengelola Kawasan Industri Pergudang Taman Tekno BSD) | D27: sulas@sinarmasland.com
A28: 27 | B28: PT. Chandra Asri Petrochemical (Kimia), Kota Cilegon | D28: annizah.gerhana@capcx.com
A29: 28 | B29: PT. Lestari Banten Energi (Listrik), Kab. Serang | D29: aris.sarwoko@gentingenergy.com
A30: 29 | B30: PT. Victory Chingluh (industri Alas kaki) Kab Tangerang | D30: noertyas.lazuardi@chingluh.com
A31: 30 | B31: PT. Modern Industrial Estate, Pengelola KI Modern Cikande Kab Serang | D31: indri.amrulloh@modernland.co.id
A32: 31 | B32: PT. Sauh Bahtera Samudera, Perusahaan Air Bersih Kota Serang | D32: wtp@sauhbahtera.co.id
A33: 32 | B33: JHL Solitaire Hotel Gading Serpong | D33: dm.sgs@jhlcollections.com
A34: 33 | B34: PT. Soll Marina (Grand Soll Marina Hotel) | D34: gm.gsmh@sollmarinahotel.com
A35: 34 | B35: Horison Ultima Ratu | D35: fom.ratuserang@horisonultimahotels.com
A36: 35 | B36: Aviary Bintaro (PT. SUMAMPAU PEMBANGUNAN LESTARI) | D36: ricky.wijaya@aviaryhotel.com cc ade@aviaryhotel.com
A37: 36 | B37: Perhimpunan Hotel dan Restoran Indonesia- Banten (PHRI Banten) | D37: bpdbanten@phri.or.id
A38: 37 | B38: Universitas Sultan Ageng Tirtayasa | D38: humas@untirta.ac.id
... A49: 48 | B49: Polyplast Dwiputra Pratama | D49: marketing@dp-chemicals.com
A50: 49 | B50: PT. Jabar Utama Wood Industry
A51: 50 | B51: Tanjung Lesung
A52: 51 | B52: Yayasan Sahabat Quran Banten
A53: 1 | B53: UNIVERSITAS FALETEHAN
A54: 2 | B54: INSTITUT KEMANDIRIAN NUSANTARA (IKNUS)
...

Sheet Sheet3
B3: =VLOOKUP(Sheet1!J2,target!$B$2:$B$369,1,) -> PT. Nicomas Gemilang (Pengelola Kawasan Industri Nikomas Gemilang)
B4: =VLOOKUP(Sheet1!J3,target!$B$2:$B$369,1,) -> #N/A | K4: =COUNT(B3:B395) -> 0
B5: =VLOOKUP(Sheet1!J4,target!$B$2:$B$369,1,) -> UNIVERSITAS ICHSAN SATYA | K5: =SUMPRODUCT(--ISNA(B3:B395)) -> 123
B6: =VLOOKUP(Sheet1!J5,target!$B$2:$B$369,1,) -> #N/A | K6: =395-3+1-123 -> 270
B7: =VLOOKUP(Sheet1!J6,target!$B$2:$B$369,1,) -> #N/A
B8: =VLOOKUP(Sheet1!J7,target!$B$2:$B$369,1,) -> #N/A
B9: =VLOOKUP(Sheet1!J8,target!$B$2:$B$369,1,) -> Universitas Bina Bangsa
B10: =VLOOKUP(Sheet1!J9,target!$B$2:$B$369,1,) -> UNIVERSITAS PAMULANG
B11: =VLOOKUP(Sheet1!J10,target!$B$2:$B$369,1,) -> INSTITUT TEKNOLOGI DAN BISNIS BINA SARANA GLOBAL
B12: =VLOOKUP(Sheet1!J11,target!$B$2:$B$369,1,) -> #N/A
B13: =VLOOKUP(Sheet1!J12,target!$B$2:$B$369,1,) -> #N/A
B14: =VLOOKUP(Sheet1!J13,target!$B$2:$B$369,1,) -> #N/A
B15: =VLOOKUP(Sheet1!J14,target!$B$2:$B$369,1,) -> #N/A
B16: =VLOOKUP(Sheet1!J15,target!$B$2:$B$369,1,) -> #N/A
B17: =VLOOKUP(Sheet1!J16,target!$B$2:$B$369,1,) -> #N/A
B18: =VLOOKUP(Sheet1!J17,target!$B$2:$B$369,1,) -> POLITEKNIK PGRI BANTEN
... B395: =VLOOKUP(Sheet1!J394,target!$B$2:$B$369,1,) -> #N/A
